Workbook

Sheet U T A
A2: This scorecard is designed to evaluate responses from a completed VPAT® (Voluntary Product Accessibility Template), also known as an Accessibility Conformance Report (ACR). VPAT® is a registered trademark of ITIC.org. The purpose of this scorecard is to standardize the assessment of ACRs submitted by vendors or derived from user testing. Please note: This scorecard does not determine whether a resource is definitively accessible. Instead, it serves as a centralized tool to help guide decisions regarding accessibility and identify potential accommodations. This file contains six worksheets. The current worksheet is 1 of 6, with content located in only column A, rows 1 through 13. Below is a summary of the remaining worksheets: Worksheet 2: Score Contains eight tables that calculate a VPAT score, grade, and a risk indicator based on ACR responses and user population. Includes: Table 1: Resource, ticket number, WCAG 2.1 score, and risk indicator. Table 2: Resource details such as cost, date of VPAT and number of users Tables 3 and 4: Accessibility scores and grades for WCAG 2.2 and 2.0 respectively. Table 5: Weighting of response categories. Table 6: Grading logic and approval methods. Table 7: Risk logic explanation. Table 8: Population segments likely to encounter accessibility barriers.
A3: Worksheet 3: ACR Record the vendor's responses from the completed VPAT®. In Column C select one of the three options: Supports (default), Partially Supports, or Does Not Support. You may either type s for Supports, p for Partially Supports or d for Does not support. Or, you may choose from the drop down list. If the vendor indicates N/A, then select Supports. If the vendor indicates not evaluated, then select Does not support. This update does away with double checking the count because no criteria can be skipped. The default is always supports. Each WCAG criterion is hyperlinked to the W3C website. User may adjust the impact categories and notes, including if a manual check was run. AAA criteria are not included. Worksheet 4: List by Impact Maps WCAG criteria to specific disability types.
A4: Worksheet 5: Roadmap Priority This list help vendors prioritize their remediaton roadmap. Worksheet 6: Versions Tracks the changes made to each version of the scorecard.
A5: Update to scoring logic: I was unable to implement the desire to drop a score based on the number of extremely important criteria not supported. I will work on this for a future update. We have opted to change the weights we are using. Any success criteria that is supported, gets the full points no matter the impact classification of Standard, Somewhat Important or Important. I reversed the weights of partially supported so that Extremely Important criteria that are partially supported receive fewer points than Standard criteria that are partially supported. We understand that everyone may not adopt this same philosophy. Feel free to customize this scorecard. This revision has all formulas updated.
A6: Accessibility Philosophy at UTA At The University of Texas at Arlington, we are committed to meeting all WCAG A/AA criteria for Electronic and Information Resources (EIR). We acknowledge the need to balance accessibility with operational constraints such as staffing, resources, and budget. This scorecard allows for a passing grade even if not all criteria are met. Our goal remains full accessibility, but practical limitations may necessitate continued use of EIRs that do not fully comply. The scorecard helps communicate necessary accommodations to the requesting department so that proper documentation for exception forms is processed in accordance with state and federal rules. For resources that receive failing scores, vendors will be provided feedback on the specific accessibility issues. Grades below A or B require submission of an EIR Accessibility Exception (EAE) form. These forms were previously known as EEAAPs (Equally Effective Accessibility Accommodation Plans). The adoption of a letter-grade system enables year-over-year comparison while supporting the evolution of our numerical scoring methodology.
A7: This scorecard does not have any protected cells. All users are welcome to modify the weights and formulas to best fit their needs. If you run across any errors or find this scoring system beneficial, please let us know.
A8: TAC refers to Texas Administrative Code https://texas-sos.appianportalsgov.com/rules-and-meetings?recordId=197309&queryAsDate=08%2F15%2F2025&interface=VIEW_TAC_SUMMARY&$locale=en_US
A9: Future goals: 1) Run a validation of the responses comparing them to each other. For instance, if 2.1.2 Keyboard Traps fails, then 2.1.1 Keyboard should also fail. Or, if 2.4.6 Headings and Labels fails then 1.3.1 Info and Relationships also fails. 2) Create a formula that would ensure a drop in the grade if more than 1 (or 2?) of the Extremely Important criteria are not supported. Make this adjustment clear to all users and editable. 3) Can AI populate the ACR worksheet from a VPAT without human input (and without error). Concern: The comments on the VPAT are important. If a human isn't completing the input, does that get lost? 4) Produce a remediation map for the vendor based on the criteria that are not supported based on the Roadmap Priority information.
A10: Scorecard created by:
A11: Laura Hopkins (she/her/hers) MS ITM, CPACC, CAPM, CTCD/CTCM
A12: EIR Compliance Lead | EIR Accessibility Coordinator
A13: The University of Texas at Arlington
... A18: Special thanks to Amy Wilkes, EIR Accessibility Specialist at UT Arlington for her assistance in creating this scorecard.

Sheet Score
A1: TTU Accessibility Scorecard
A2: Resource | B2: Details
A3: Name of EIR:
A4: Ticket Number:
A5: Accessibility Grade 2.1 | B5: =+H37 -> A
A6: Risk Level | B6: =IF(H37="A","Low",IF(OR(B21="Yes",B19+B20>=5000),"Very high",IF(AND(B21="No",B19+B20>=501,B19+B20<=5000),"High",IF(AND(B21="No",B19+B20>=51,B19+B20<=500),"Moderate",IF(AND(B21="No",B19+B20<=50),"Low",""))))) -> Low
A8: Resource details
A9: Details | B9: Response | C9: Notes | D9: Comments
A10: Manufacturer Name:
A11: URL:
A12: VPAT® Version:
A13: Date of VPAT®: | C13: =IF(((DATEDIF($B$13,$B$16,"D")/365)>2),"CAUTION VPAT IS > 2 YEARS OLD","Current") -> Current | D13: C44 calculates with B47
A14: Did the assessment include manual testing? | B14: Yes | C14: If no, should VPAT be considered?
A15: Scored by:
A16: Date Graded:
A17: Annual Cost: | B17: 30000 | C17: Crucial to score
A18: Was an NDA executed in order to receive the ACR? | B18: No | C18: If an NDA is required, review carefully for confidence.
A19: How many students use this resource annually? (enter a number) | B19: 0 | C19: Crucial to score
A20: How many employees (faculty/staff) use this resource annually? | B20: 10 | C20: Crucial to score
A21: Is this resource of use by the public? | B21: No | C21: Crucial to score
A22: Select a confidence level of ACR (high, medium, low). | B22: Medium | C22: If confidence is low, discard the ACR.
A23: Did scorer adjust impact level of any success criteria? | C23: If yes, explain
A25: Grade per WCAG 2.2
A26: Impact Category WCAG 2.2 | B26: 2.2 Not Supported/ Not Evaluated | C26: 2.2 Partially Supports | D26: 2.2 Supports | E26: 2.2 Total Success Criteria | F26: 2.2 Score | G26: 2.2 Perfect Score | H26: 2.2 Grade | I26: 2.2 Grade Range | J26: Minimum score for 2.1
A27: Extremely Important 2.2 | B27: =COUNTIFS(ACR!$B$2:$B$57,"Extremely Important",ACR!$C$2:$C$57,"Does not support",ACR!$H$2:$H$57,1) -> 0 | C27: =COUNTIFS(ACR!$B$2:$B$57,"Extremely Important",ACR!$C$2:$C$57,"Partially supports",ACR!$H$2:$H$57,1) -> 0 | D27: =COUNTIFS(ACR!$B$2:$B$57,"Extremely Important",ACR!$C$2:$C$57,"Supports",ACR!$H$2:$H$57,1) -> 18 | I27: A - | J27: minimum 5320, 95% of perfect
A28: Somewhat Important 2.2 | B28: =COUNTIFS(ACR!$B$2:$B$57,"Somewhat Important",ACR!$C$2:$C$57,"Does not support",ACR!$H$2:$H$57,1) -> 0 | C28: =COUNTIFS(ACR!$B$2:$B$57,"Somewhat Important",ACR!$C$2:$C$57,"Partially supports",ACR!$H$2:$H$57,1) -> 0 | D28: =COUNTIFS(ACR!$B$2:$B$57,"Somewhat Important",ACR!$C$2:$C$57,"Supports",ACR!$H$2:$H$57,1) -> 14 | I28: B - | J28: minimum 4760, 85% of perfect and no student/public use
A29: Standard 2.2 | B29: =COUNTIFS(ACR!$B$2:$B$57,"Standard",ACR!$C$2:$C$57,"Does not support",ACR!$H$2:$H$57,1) -> 0 | C29: =COUNTIFS(ACR!$B$2:$B$57,"Standard",ACR!$C$2:$C$57,"Partially supports",ACR!$H$2:$H$57,1) -> 0 | D29: =COUNTIFS(ACR!$B$2:$B$57,"Standard",ACR!$C$2:$C$57,"Supports",ACR!$H$2:$H$57,1) -> 21 | I29: C - | J29: Limited use and cost
A30: Success Criteria Totals 2.2 | B30: =+B27+B28+B29 -> 0 | C30: =+C27+C28+C29 -> 0 | D30: =+D27+D28+D29 -> 53 | E30: =+B27+C27+D27+B28+C28+D28+B29+C29+D29 -> 53 | F30: =(B27*$B$41)+(B28*$B$42)+(B29*$B$43)+(C27*$C$41)+(C28*$C$42)+(C29*$C$43)+(D27*$D$41)+(D28*$D$42)+(D29*$D$43) -> 5300 | G30: =56*100 -> 5600 | H30: =IF(G30=0,"N/A",IF(F30/G30>=0.95,"A",IF(AND(F30/G30>=0.85,B19=0,B21="No"),"B",IF(AND(F30/G30<=0.95,AND(B19<=50,B20<=50),B21="No",B17<=25000),"C",IF(B17<25000,"D","F"))))) -> B | I30: D/F - | J30: EIR Accessibility Exception Paperwork Required
A32: Grade per WCAG 2.1
A33: Impact Category WCAG 2.1 | B33: 2.1 Not Supported/ Not Evaluated | C33: 2.1 Partially Supports | D33: 2.1 Supports | E33: 2.1 Total Success Criteria | F33: 2.1 Score | G33: 2.1 Perfect Score | H33: 2.1 Grade | I33: 2.1 Grade Range | J33: Minimum score for 2.1
A34: Extremely Important 2.1 | B34: =COUNTIFS(ACR!$B$2:$B$57,"Extremely Important",ACR!$C$2:$C$57,"Does not support",ACR!$G$2:$G$57,1) -> 0 | C34: =COUNTIFS(ACR!$B$2:$B$57,"Extremely Important",ACR!$C$2:$C$57,"Partially supports",ACR!$G$2:$G$57,1) -> 0 | D34: =COUNTIFS(ACR!$B$2:$B$57,"Extremely Important",ACR!$C$2:$C$57,"Supports",ACR!$G$2:$G$57,1) -> 17 | I34: A - | J34: minimum 4750, 95% of perfect
A35: Somewhat Important 2.1 | B35: =COUNTIFS(ACR!$B$2:$B$57,"Somewhat Important",ACR!$C$2:$C$57,"Does not support",ACR!$G$2:$G$57,1) -> 0 | C35: =COUNTIFS(ACR!$B$2:$B$57,"Somewhat Important",ACR!$C$2:$C$57,"Partially supports",ACR!$G$2:$G$57,1) -> 0 | D35: =COUNTIFS(ACR!$B$2:$B$57,"Somewhat Important",ACR!$C$2:$C$57,"Supports",ACR!$G$2:$G$57,1) -> 11 | I35: B - | J35: minimum 4250, 85% of perfect and no student/public use
A36: Standard 2.1 | B36: =COUNTIFS(ACR!$B$2:$B$57,"Standard",ACR!$C$2:$C$57,"Does not support",ACR!$G$2:$G$57,1) -> 0 | C36: =COUNTIFS(ACR!$B$2:$B$57,"Standard",ACR!$C$2:$C$57,"Partially supports",ACR!$G$2:$G$57,1) -> 0 | D36: =COUNTIFS(ACR!$B$2:$B$57,"Standard",ACR!$C$2:$C$57,"Supports",ACR!$G$2:$G$57,1) -> 20 | I36: C - | J36: Limited use and cost
A37: Success Criteria Totals 2.1 | B37: =+B34+B35+B36 -> 0 | C37: =+C34+C35+C36 -> 0 | D37: =+D34+D35+D36 -> 48 | E37: =+B34+C34+D34+B35+C35+D35+B36+C36+D36 -> 48 | F37: =(B34*$B$41)+(B35*$B$42)+(B36*$B$43)+(C34*$C$41)+(C35*$C$42)+(C36*$C$43)+(D34*$D$41)+(D35*$D$42)+(D36*$D$43) -> 4800 | G37: =+Table68[[#This Row],[2.1 Total Success Criteria]]*100 -> 4800 | H37: =IF(G37=0,"N/A",IF(F37/G37>=0.95,"A",IF(AND(F37/G37>=0.85,B19=0,B21="No"),"B",IF(AND(F37/G37<=0.95,AND(B19<=50,B20<=50),B21="No",B17<=25000),"C",IF(B17<25000,"D","F"))))) -> A | I37: D/F - | J37: EIR Accessibility Exception Paperwork Required
A39: Weights Logic
A40: Weights | B40: Not Support / Not Evaluated | C40: Partially Supports | D40: Supports
A41: Extremely Important | B41: 0.01 | C41: 30 | D41: 100
A42: Somewhat Important | B42: 0.01 | C42: 40 | D42: 100
A43: Standard | B43: 0.01 | C43: 50 | D43: 100
A45: Logic Table for Grade
...

Sheet ACR
A1: VPAT Criteria 2.4 - Enter a 1 in the proper column to indicate the response from the vendor. | B1: Impact | C1: Response | D1: Validation Method [Source: Siteimprove] | E1: Comments or Notes | F1: WCAG 2.0 | G1: WCAG 2.1 | H1: WCAG 2.2
A2: 1.1.1 Non-text Content (Level A) | B2: Extremely important | C2: Supports | D2: Automated | F2: 1 | G2: 1 | H2: 1
A3: 1.2.1 Audio-only and Video-only (Prerecorded) (Level A) | B3: Somewhat important | C3: Supports | D3: Automated | F3: 1 | G3: 1 | H3: 1
A4: 1.2.2 Captions (Prerecorded) (Level A) | B4: Extremely important | C4: Supports | D4: Automated | F4: 1 | G4: 1 | H4: 1
A5: 1.2.3 Audio Description or Media Alternative (Prerecorded) (Level A) | B5: Somewhat important | C5: Supports | D5: Automated | F5: 1 | G5: 1 | H5: 1
A6: 1.3.1 Info and Relationships (Level A) | B6: Extremely important | C6: Supports | D6: Automated | F6: 1 | G6: 1 | H6: 1
A7: 1.3.2 Meaningful Sequence (Level A) | B7: Extremely important | C7: Supports | D7: Manual | F7: 1 | G7: 1 | H7: 1
A8: 1.3.3 Sensory Characteristics (Level A) | B8: Standard | C8: Supports | D8: Manual | F8: 1 | G8: 1 | H8: 1
A9: 1.4.1 Use of Color (Level A) | B9: Extremely important | C9: Supports | D9: Automated | F9: 1 | G9: 1 | H9: 1
A10: 1.4.2 Audio Control (Level A) | B10: Somewhat important | C10: Supports | D10: Automated | F10: 1 | G10: 1 | H10: 1
A11: 2.1.1 Keyboard (Level A) | B11: Extremely important | C11: Supports | D11: Automated | F11: 1 | G11: 1 | H11: 1
A12: 2.1.2 No Keyboard Trap (Level A) | B12: Extremely important | C12: Supports | D12: Manual | F12: 1 | G12: 1 | H12: 1
A13: 2.1.4 Character Key Shortcuts (Level A 2.1 and 2.2) | B13: Standard | C13: Supports | D13: Manual | F13: 0 | G13: 1 | H13: 1
... A27: 3.2.2 On Input (Level A) | B27: Somewhat important | C27: Supports | D27: Manual | F27: 1 | G27: 1 | H27: 1
A28: 3.2.6 Consistent Help (Level A 2.2) | B28: Somewhat important | C28: Supports | D28: Manual | E28: New in 2.2 | F28: 0 | G28: 0 | H28: 1
A29: 3.3.1 Error Identification (Level A) | B29: Somewhat important | C29: Supports | D29: Manual | F29: 1 | G29: 1 | H29: 1
A30: 3.3.2 Labels or Instructions (Level A) | B30: Somewhat important | C30: Supports | D30: Manual | F30: 1 | G30: 1 | H30: 1
A31: 3.3.7 Redundent Entry (Level 2.2) | B31: Somewhat important | C31: Supports | D31: Manual | E31: New in 2.2 | F31: 0 | G31: 0 | H31: 1
A32: 4.1.1 Parsing (Level A) | B32: Standard | C32: Supports | D32: Automated | E32: For WCAG 2.0 and 2.1, the September 2023 errata update indicates this criterion is always supported. | F32: 1 | G32: 1 | H32: 1
A33: 4.1.2 Name, Role, Value (Level A) | B33: Standard | C33: Supports | D33: Automated | F33: 1 | G33: 1 | H33: 1
A34: 1.2.4 Captions (Live) (Level AA) | B34: Extremely important | C34: Supports | D34: Manual | F34: 1 | G34: 1 | H34: 1
A35: 1.2.5 Audio Description (Prerecorded) (Level AA) | B35: Somewhat important | C35: Supports | D35: Automated | F35: 1 | G35: 1 | H35: 1
A36: 1.3.4 Orientation (Level AA 2.1 and 2.2) | B36: Standard | C36: Supports | D36: Automated | F36: 0 | G36: 1 | H36: 1
A37: 1.3.5 Identify Input Purpose (Level A 2.1 and 2.2) | B37: Standard | C37: Supports | D37: Automated | F37: 0 | G37: 1 | H37: 1
A38: 1.4.3 Contrast (Minimum) (Level AA) | B38: Extremely important | C38: Supports | D38: Automated | F38: 1 | G38: 1 | H38: 1
A39: 1.4.4 Resize text (Level AA) | B39: Extremely important | C39: Supports | D39: Automated | F39: 1 | G39: 1 | H39: 1
A40: 1.4.5 Images of Text (Level AA) | B40: Somewhat important | C40: Supports | D40: Manual | F40: 1 | G40: 1 | H40: 1
A41: 1.4.10 Reflow (Level A 2.1 and 2.2) | B41: Extremely important | C41: Supports | D41: Automated | F41: 0 | G41: 1 | H41: 1
A42: 1.4.11 Non-text Contrast (Level A 2.1 and 2.2) | B42: Somewhat important | C42: Supports | D42: Manual | F42: 0 | G42: 1 | H42: 1
A43: 1.4.12 Text Spacing (Level A 2.1 and 2.2) | B43: Standard | C43: Supports | D43: Automated | F43: 0 | G43: 1 | H43: 1
A44: 1.4.13 Content on Hover or Focus (Level AA, 2.1 and 2.2) | B44: Standard | C44: Supports | D44: Manual | F44: 0 | G44: 1 | H44: 1
... A47: 2.4.7 Focus Visible (Level AA) | B47: Extremely important | C47: Supports | D47: Automated | F47: 1 | G47: 1 | H47: 1
A48: 2.4.11 Focus Not Obscured (Level AA, WCAG 2.2) | B48: Standard | C48: Supports | D48: Manual | E48: New in 2.2 | F48: 0 | G48: 0 | H48: 1
A49: 2.5.7 Dragging Movements (Level AA, 2.2) | B49: Somewhat important | C49: Supports | D49: Manual | E49: New in 2.2 | F49: 0 | G49: 0 | H49: 1
A50: 2.5.8 Target Size (Level AA, 2.2) | B50: Extremely important | C50: Supports | D50: Automated | E50: New in 2.2 | F50: 0 | G50: 0 | H50: 1
A51: 3.1.2 Language of Parts (Level AA) | B51: Standard | C51: Supports | D51: Automated | F51: 1 | G51: 1 | H51: 1
A52: 3.2.3 Consistent Navigation (Level AA) | B52: Standard | C52: Supports | D52: Manual | F52: 1 | G52: 1 | H52: 1
A53: 3.2.4 Consistent Identification (Level AA) | B53: Standard | C53: Supports | D53: Manual | F53: 1 | G53: 1 | H53: 1
A54: 3.3.3 Error Suggestion (Level AA) | B54: Standard | C54: Supports | D54: Manual | F54: 1 | G54: 1 | H54: 1
A55: 3.3.4 Error Prevention (Legal, Financial, Data) (Level AA) | B55: NA | C55: Supports | D55: Manual | F55: 1 | G55: 1 | H55: 1
...

Sheet List by Impact
A1: List of WCAG Criteria and which disabilities are impacted. | B1: WCAG Version | C1: Row on Response Tab | D1: Blindness | E1: Low Vision | F1: Colorblindness | G1: Hearing Loss | H1: Cognitive Disorders | I1: Motor Disabilities | J1: Epilepsy
A2: 1.1.1 Non-text Content (Level A) | B2: 2 | C2: 2 | D2: 1 | E2: 1 | F2: 1 | G2: 0 | H2: 0 | I2: 0 | J2: 0
A3: 1.2.1 Audio-only and Video-only (Prerecorded) (Level A) | B3: 2 | C3: 3 | D3: 1 | E3: 1 | F3: 0 | G3: 1 | H3: 1 | I3: 0 | J3: 0
A4: 1.2.2 Captions (Prerecorded) (Level A) | B4: 2 | C4: 4 | D4: 1 | E4: 1 | F4: 0 | G4: 1 | H4: 1 | I4: 0 | J4: 0
A5: 1.2.3 Audio Description or Media Alternative (Prerecorded) (Level A) | B5: 2 | C5: 5 | D5: 1 | E5: 1 | F5: 0 | G5: 1 | H5: 1 | I5: 0 | J5: 0
A6: 1.3.1 Info and Relationships (Level A) | B6: 2 | C6: 6 | D6: 1 | E6: 0 | F6: 0 | G6: 0 | H6: 0 | I6: 0 | J6: 0
A7: 1.3.2 Meaningful Sequence (Level A) | B7: 2 | C7: 7 | D7: 1 | E7: 0 | F7: 0 | G7: 0 | H7: 1 | I7: 0 | J7: 0
A8: 1.3.3 Sensory Characteristics (Level A) | B8: 2 | C8: 8 | D8: 1 | E8: 1 | F8: 1 | G8: 1 | H8: 1 | I8: 1 | J8: 0
A9: 1.4.1 Use of Color (Level A) | B9: 2 | C9: 9 | D9: 0 | E9: 1 | F9: 1 | G9: 0 | H9: 0 | I9: 0 | J9: 0
A10: 1.4.2 Audio Control (Level A) | B10: 2 | C10: 10 | D10: 1 | E10: 1 | F10: 0 | G10: 1 | H10: 1 | I10: 1 | J10: 0
A11: 2.1.1 Keyboard (Level A) | B11: 2 | C11: 11 | D11: 1 | E11: 1 | F11: 0 | G11: 0 | H11: 1 | I11: 1 | J11: 0
A12: 2.1.2 No Keyboard Trap (Level A) | B12: 2 | C12: 12 | D12: 1 | E12: 1 | F12: 0 | G12: 0 | H12: 1 | I12: 1 | J12: 0
A13: 2.1.4 Character Key Shortcuts (Level A 2.1 and 2.2) | B13: 2.1 | C13: 13 | D13: 1 | E13: 1 | F13: 0 | G13: 0 | H13: 1 | I13: 1 | J13: 0
... A57: 4.1.3 Status Messages (Level AA 2.1 and 2.2) | B57: 2.1 | C57: 57 | D57: 1 | E57: 1 | F57: 0 | G57: 0 | H57: 1 | I57: 0 | J57: 0
A58: Totals | D58: =SUM(D2:D57) -> 42 | E58: =SUM(E2:E57) -> 48 | F58: =SUM(F2:F57) -> 15 | G58: =SUM(G2:G57) -> 10 | H58: =SUM(H2:H57) -> 53 | I58: =SUM(I2:I57) -> 33 | J58: =SUM(J2:J57) -> 3
A59: % of U S Adult Population | D59: 0.0283 | E59: 0.08 | F59: 0.049 | G59: 0.057 | H59: 0.109 | I59: 0.11 | J59: 0.012
A60: This worksheet has been edited and modified but was based on work shared by: Karole Schroeder, CPACC (she/her/hers) Electronic and Information Resources Accessibility Coordinator (EIRAC) Office of Information Security | Division of Information Technology, Texas A & M University Corpus Christi
A61: © UTA Proprietary - please do not share without our permission - accessiblity@uta.edu

Sheet Roadmap
A1: VPAT Criteria | B1: Roadmap Priority
A2: 1.4.3 Contrast (Minimum) (Level AA) | B2: 1
A3: 1.4.1 Use of Color (Level A) | B3: 2
A4: 1.4.4 Resize text (Level AA) | B4: 3
A5: 2.4.6 Headings and Labels (Level AA) | B5: 4
A6: 2.1.1 Keyboard (Level A) | B6: 5
A7: 2.1.2 No Keyboard Trap (Level A) | B7: 6
A8: 1.3.2 Meaningful Sequence (Level A) | B8: 7
A9: 1.2.2 Captions (Prerecorded) (Level A) | B9: 8
A10: 1.2.1 Audio-only and Video-only (Prerecorded) (Level A) | B10: 9
A11: 1.2.3 Audio Description or Media Alternative (Prerecorded) (Level A) | B11: 10
A12: 2.3.1 Three Flashes or Below Threshold (Level A) | B12: 11
A13: 1.2.4 Captions (Live) (Level AA) | B13: 12
... A56: 2.4.11 Focus Not Obscured (Level AA, WCAG 2.2) | B56: 55
A57: 4.1.1 Parsing (Level A) | B57: n/a

Sheet Versions
A1: Date | B1: Updates | C1: Revision number
A2: 45894 | B2: Dropped references to 2.0 on Score tab | C2: 26
A3: 45890 | B3: Updated from 3 response columns to a single column with a pick list; updated all formulas | C3: 25
A4: 45890 | B4: Added formula in col E of the ACR tab to automatically change from 1 to 0 if a 1 is entered in either column C or D | C4: 24
A5: 45890 | B5: Changed Grade formula from >=.80 to <=.89; hid text in Col I and J to reduce confusion | C5: 23d
A6: 45890 | B6: Continued formula updates to secure proper responses | C6: 23c
A7: 45889 | B7: Continued issues with the B grade and issue with the D grade on 2.1; updated 'missing criteria' response | C7: 23b
A8: 45889 | B8: The B Grade was not taking into account student use properly. | C8: 23a
A9: 45887 | B9: Updated weights for supported criteria - no different between the Extremely Important, Somewhat Important or Standard criteria if supported | C9: 23
A10: 45884 | B10: Corrected score of C so that it can be applied to those with less than 50 users and costs less than 25k, | C10: 22c
A11: 45882 | B11: The risk indicator was wrong because the score formula was wrong - corrected. Added qualifer that if more than 1 Extremely Important criteria is not supported, the score is reduced by 5% | C11: 22b
A12: 45881 | B12: Corrected Risk Level to reflect WCAG 2.1 grade; added text message if number of criteria is not correct | C12: 22a
A13: 45880 | B13: Major Revision: Removed number of users from accessibility score/grade, all WCAG scores are on the same worksheet | C13: 22
A14: 45875 | B14: Corrected Score so that it takes into account the response for public use. | C14: 21
A15: 45777 | B15: Corrections to formulas for Conditional Pass and cleared conditional formatting on B6 | C15: 20
A16: 45632 | B16: Autopopulate details on resource | C16: 19
A17: 45608 | B17: Added 2.0 tab, added 2.1 tab, corrected formulas for impacted populations on 2.0 tab, added Roadmap tabd, corrected errors | C17: 18
A18: 45467 | B18: Corrected formulas in Disabilities Impacted tables on Score tab | C18: 17
A19: 45400 | B19: Added a greater than sign before the equal sign in the IF statement to calculate Vendor Response | C19: 16
A20: 45322 | B20: Removed the text about less than 50 employees for a B score Conditional approval | C20: 15
A21: 45202 | B21: Updated the scale and corrected some of the formulas | C21: 14
A22: 45195 | B22: Updated from standard to extremely important rows 6 and 44 | C22: 13
A23: 45162 | B23: Added indicator for each criteria if automated or manual check | C23: 12
A24: 45099 | B24: updated information on the first worksheet for tabs 4 and 5 | C24: 11
... A29: 45068 | B29: Moved Headings/Labels | C29: 7
A30: 45067 | B30: Added Letter Accessibility Grade. Added Risk Grade. Added legends for both
